Workbook

Sheet Dashboard
B2: #VALUE! | C2: Schedule supervision | E2: Planned/Arrival Avg.time | F2: =AVERAGE(Control!E5:E160)-AVERAGE(Control!F5:F160) -> 0.0016854354 | K2: Total Installed | L2: =COUNTIF(Control!L5:L97, "*completed*") -> 70
E4: Arrival time | F4: =AVERAGE(Control!F3:F95) -> 0.22888889 | H4: Start date | I4: =Control!D5 -> 44490 | K4: # sites installed | L4: =COUNTIF(Control!L5:L97,"completed") -> 70
B6: Accumulated time Spent all sites [hh]:[mm]:[ss] | C6: =Control!I4 -> 5.5277778 | E6: Real/Arrival Avg.time | F6: =AVERAGE(Control!F5:F97)-AVERAGE(Control!G5:G97) -> -0.011222222 | H6: The most recent installation | I6: {=LOOKUP(2, 1/((Control!D5:D97<>"")*(Control!L5:L97="completed")), Control!D5:D97)} -> 44672 | K6: Next sites on roadmap | L6: =COUNTIF(Control!L5:L97, "*planned*") -> 0
K7: Total Quantity sites planned | L7: 90
B9: Average time spent per site [hh]:[mm]:[ss] | C9: =AVERAGE(Control!I5:I97) -> 0.11055556 | E9: Start time accumulated deviation [hh]:[mm]:[ss] | F9: =F2-F6 -> 0.012907658 | H9: How many calendar days transcurred | I9: =IF(ISBLANK(Control!D5),"", TODAY()-Control!D5) -> 190 | K9: Progress | L9: =L2/Dashboard!L7 -> 0.77777778

Sheet Control
A1: Status of installations completed and scheduled
A2: Devices | D2: Initial Schedule | G2: Execution | M2: Site | O2: Comments
A3: Devices | B3: Serial | C3: Reference | D3: Planned Date | E3: Planned Time | F3: Arrival time | G3: Real Start time | H3: End time | I3: Duration | J3: Early arrive | K3: Previous date | L3: Status | M3: Address | N3: Loc. Code | O3: Notes
E4: =AVERAGE(E5:E97) -> 0.23057432 | F4: =AVERAGE(F5:F97) -> 0.22888889 | G4: =AVERAGE(G5:G97) -> 0.24011111 | I4: =SUM(I5:I95) -> 5.5277778 | J4: =AVERAGE(J5:J97) -> -0.0013888889 | T4: waiting time for site access
A5: MX250-HW | B5: Q3LC-527T-VHDP | C5: Firewall | D5: 44490 | E5: 0.33333333 | F5: 0.35138889 | G5: 0.35208333 | H5: 0.63125 | I5: =H5-G5 -> 0.27916667 | J5: =Tabla4[[#This Row],[Planned Time]]-Tabla4[[#This Row],[Arrival time]] -> -0.018055556 | L5: Completed | M5: Financial Park, piso 41 | N5: 0 | O5: No comments
A6: MR44-HW | B6: Q3AL-EBTB-ANH4 | C6: AP | D6: 44495 | E6: 0.041666667 | F6: 0.029861111 | G6: 0.03125 | H6: 0.16319444 | I6: =H6-G6 -> 0.13194444 | J6: =Tabla4[[#This Row],[Planned Time]]-Tabla4[[#This Row],[Arrival time]] -> 0.011805556 | L6: Completed | M6: San Vicente, chilibre | N6: 100 | O6: AP not available-we did update-ports ID-ports-organizing
A7: MR44-HW | B7: Q3AL-XD7N-RXMU | C7: AP | D7: 44496 | E7: 0.20833333 | F7: 0.20486111 | G7: 0.20694444 | H7: 0.40277778 | I7: =H7-G7 -> 0.19583333 | J7: =Tabla4[[#This Row],[Planned Time]]-Tabla4[[#This Row],[Arrival time]] -> 0.0034722222 | L7: Completed | M7: Villa Lucre | N7: P25 | O7: No comments
A8: MR44-HW | B8: Q3AL-QFHA-F7MB | C8: AP | D8: 44500 | E8: 0.20833333 | L8: Cancelled | M8: Royal Blue Plaza | N8: NA | O8: Was cancelled twice, now we are watting a new date
A9: MX67-HW | B9: Q2FY-8J33-QYL9 | C9: Firewall | D9: lunes, 12 de enero de 2026 | E9: 0.29166667 | F9: 0.28472222 | G9: 0.29166667 | H9: 0.39375 | I9: =H9-G9 -> 0.10208333 | J9: =Tabla4[[#This Row],[Planned Time]]-Tabla4[[#This Row],[Arrival time]] -> 0.0069444444 | L9: Completed | M9: Los Pueblos | N9: P51 | O9: No comments
A10: MR44-HW | B10: Q3AL-VFSD-6SPG | C10: AP | D10: miercoles, 14 de enero de 2026 | E10: 0.16666667 | F10: 0.18402778 | G10: 0.18541667 | H10: 0.35902778 | I10: =H10-G10 -> 0.17361111 | J10: =Tabla4[[#This Row],[Planned Time]]-Tabla4[[#This Row],[Arrival time]] -> -0.017361111 | L10: Completed | M10: Villa Catalina Airport Plaza | N10: P90 | O10: No comments
A11: MX68-HW | B11: Q2KY-S5FG-GAZ2 | C11: Firewall | D11: jueves, 15 de enero de 2026 | E11: 0.16666667 | F11: 0.17569444 | G11: 0.17569444 | H11: 0.36597222 | I11: =H11-G11 -> 0.19027778 | J11: =Tabla4[[#This Row],[Planned Time]]-Tabla4[[#This Row],[Arrival time]] -> -0.0090277778 | L11: Completed | M11: C.C. Plaza Las Americas/Ofibodegas Tocumen | N11: P72 | O11: No comments
A12: MX67-HW | B12: Q2FY-8HA6-3Z8N | C12: Firewall | D12: " | E12: after the previous | L12: Completed | M12: CDP - Plaza las Americas | N12: P72K1 | O12: No comments
A13: MR44-HW | B13: Q3AL-6U99-GPCZ | C13: AP | D13: viernes, 16 de enero de 2026 | E13: 0.16666667 | F13: 0.16875 | G13: 0.17291667 | H13: 0.30347222 | I13: =H13-G13 -> 0.13055556 | J13: =Tabla4[[#This Row],[Planned Time]]-Tabla4[[#This Row],[Arrival time]] -> -0.0020833333 | L13: Completed | M13: Via España | N13: P02 | O13: No comments
A14: MR44-HW | B14: Q3AL-S54A-R6A8 | C14: AP | D14: lunes, 19 de enero de 2026 | E14: 0.20833333 | F14: 0.20902778 | G14: 0.21666667 | H14: 0.51041667 | I14: =H14-G14 -> 0.29375 | J14: =Tabla4[[#This Row],[Planned Time]]-Tabla4[[#This Row],[Arrival time]] -> -0.00069444444 | L14: Completed | M14: CC Los Pueblos | N14: P37 | O14: No comments
A15: MR36H-HW | B15: Q3KB-HR6R-WHFS | C15: AP | D15: " | E15: after the previous | L15: Completed | M15: CDP - Los Pueblos | N15: P37K1 | O15: No comments
A16: MR44-HW | B16: Q3AL-2GZ4-VDGJ | C16: AP | D16: miercoles, 21 de enero de 2016 | E16: 0.22916667 | F16: 0.22152778 | G16: 0.22361111 | H16: 0.31666667 | I16: =H16-G16 -> 0.093055556 | J16: =Tabla4[[#This Row],[Planned Time]]-Tabla4[[#This Row],[Arrival time]] -> 0.0076388889 | L16: Completed | M16: La Siesta | N16: P24 | O16: No comments
A17: MX67-HW | B17: Q2FY-8GDK-TZG9 | C17: Firewall | D17: jueves, 22 de enero de 2026 | E17: 0.25 | F17: 0.24930556 | G17: 0.25416667 | H17: 0.30763889 | I17: =H17-G17 -> 0.053472222 | J17: =Tabla4[[#This Row],[Planned Time]]-Tabla4[[#This Row],[Arrival time]] -> 0.00069444444 | L17: Completed | M17: Agora Chanis | N17: P27 | O17: No comments
A18: MX67-HW | B18: Q2FY-8JQA-G6KE | C18: Firewall | D18: viernes, 23 de enero de 2026 | E18: 0.33333333 | F18: 0.29444444 | G18: 0.32291667 | H18: 0.4125 | I18: =H18-G18 -> 0.089583333 | J18: =Tabla4[[#This Row],[Planned Time]]-Tabla4[[#This Row],[Arrival time]] -> 0.038888889 | L18: Completed | M18: Metromall | N18: P59 | O18: No comments
A19: MX68-HW | B19: Q2KY-S7L9-YJMR | C19: Firewall | D19: " | E19: after the previous | L19: Completed | M19: CDP - Metromall | N19: P59K1 | O19: No comments
A20: MR44-HW | B20: Q3AL-TW7V-8GXE | C20: AP | D20: lunes, 26 de enero de 2026 | E20: 0.20833333 | F20: 0.2125 | G20: 0.21944444 | H20: 0.51736111 | I20: =H20-G20 -> 0.29791667 | J20: =Tabla4[[#This Row],[Planned Time]]-Tabla4[[#This Row],[Arrival time]] -> -0.0041666667 | L20: Completed | M20: La Doña | N20: P44 | O20: La hora de inicio fue cambiada de la 5am para las 7am
A21: MX68-HW | B21: Q2KY-S4PC-G58N | C21: Firewall | D21: " | E21: after the previous | L21: Completed | M21: CDP - Terminal de transporte La Doña | N21: P44K1 | O21: No comments
A22: MX68-HW | B22: Q2KY-S3Y3-R59J | C22: Firewall | D22: " | E22: after the previous | L22: Completed | M22: CDP - Centro comercial Super Xtra | N22: P44K2 | O22: No comments
A23: MR44-HW | B23: Q3AL-2VWX-JGQM | C23: AP | D23: martes, 27 de enero de 2026 | E23: 0.20833333 | F23: 0.21180556 | G23: 0.21319444 | H23: 0.60555556 | I23: =H23-G23 -> 0.39236111 | J23: =Tabla4[[#This Row],[Planned Time]]-Tabla4[[#This Row],[Arrival time]] -> -0.0034722222 | L23: Completed | M23: El Parador | N23: P10 | O23: No comments
A24: MR36H-HW | B24: Q3KB-A6SM-3D3N | C24: AP | D24: " | E24: after the previous | L24: Completed | M24: CDP - Super Xtra Las Acacias | N24: P10K1 | O24: No comments
A25: MR44-HW | B25: Omited | C25: AP | D25: lunes, 02 de febrero de 2026 | E25: 0.29166667 | F25: 0.29513889 | G25: 0.30416667 | H25: 0.46805556 | I25: =H25-G25 -> 0.16388889 | J25: =Tabla4[[#This Row],[Planned Time]]-Tabla4[[#This Row],[Arrival time]] -> -0.0034722222 | L25: Completed | M25: Altaplaza Mall | N25: P33 | O25: No comments
A26: MR36-HW | B26: Q3KB-KN95-ABMP | C26: AP | D26: " | E26: after the previous | L26: Completed | M26: CDP - Alta Plaza | N26: P33K1 | O26: No comments
A27: MR44-HW | B27: Q3AL-UD79-BZAP | C27: AP | D27: martes, 03 de febrero de 2026 | E27: 0.20833333 | F27: 0.22361111 | G27: 0.22638889 | H27: 0.26111111 | I27: =H27-G27 -> 0.034722222 | J27: =Tabla4[[#This Row],[Planned Time]]-Tabla4[[#This Row],[Arrival time]] -> -0.015277778 | L27: Completed | M27: Plaza Centennial | N27: P52 | O27: No comments
A28: MR44-HW | B28: Q3AL-TVLS-VAW8 | C28: AP | D28: miercoles, 04 de febrero de 2026 | E28: 0.20833333 | F28: 0.20763889 | G28: 0.22013889 | H28: 0.27152778 | I28: =H28-G28 -> 0.051388889 | J28: =Tabla4[[#This Row],[Planned Time]]-Tabla4[[#This Row],[Arrival time]] -> 0.00069444444 | L28: Completed | M28: Av. Ernesto T. Lefevre y Calle 82 Este | N28: P86 | O28: No comments
A29: MR44-HW | B29: Q3AL-GKUS-Y8ZZ | C29: AP | D29: jueves, 05 de febrero de 2026 | E29: 0.20833333 | F29: 0.21597222 | G29: 0.24444444 | H29: 0.28402778 | I29: =H29-G29 -> 0.039583333 | J29: =Tabla4[[#This Row],[Planned Time]]-Tabla4[[#This Row],[Arrival time]] -> -0.0076388889 | L29: Completed | M29: Via Cincuentenario Esq. Av. 4 C Sur | N29: P68 | O29: No comments
A30: MR44-HW | B30: Q3AL-NCMM-7FKC | C30: AP | D30: viernes, 06 de febrero de 2026 | E30: 0.20833333 | F30: 0.23402778 | G30: 0.23958333 | H30: 0.27361111 | I30: =H30-G30 -> 0.034027778 | J30: =Tabla4[[#This Row],[Planned Time]]-Tabla4[[#This Row],[Arrival time]] -> -0.025694444 | L30: Completed | M30: Plaza Versalles | N30: P63 | O30: No comments
A31: MR44-HW | B31: Q3AL-XUEQ-X8KC | C31: AP | D31: lunes, 09 de febrero de 2026 | E31: 0.20833333 | F31: 0.21111111 | G31: 0.24930556 | H31: 0.27430556 | I31: =H31-G31 -> 0.025 | J31: =Tabla4[[#This Row],[Planned Time]]-Tabla4[[#This Row],[Arrival time]] -> -0.0027777778 | L31: Completed | M31: Transístmica con Vía Brasil, | N31: P11 | O31: No comments
A32: MR44-HW | B32: Q3AL-AEZ8-Y3UR | C32: AP | D32: martes, 10 de febrero de 2026 | E32: 0.20833333 | F32: 0.2125 | G32: 0.24861111 | H32: 0.29722222 | I32: =H32-G32 -> 0.048611111 | J32: =Tabla4[[#This Row],[Planned Time]]-Tabla4[[#This Row],[Arrival time]] -> -0.0041666667 | L32: Completed | M32: Calle 50 | N32: P04 | O32: No comments
A33: MR44-HW | B33: Q3AL-5JTA-YMUT | C33: AP | D33: miercoles, 11 de febrero de 2026 | E33: 0.22916667 | F33: 0.23125 | G33: 0.23263889 | H33: 0.26805556 | I33: =H33-G33 -> 0.035416667 | J33: =Tabla4[[#This Row],[Planned Time]]-Tabla4[[#This Row],[Arrival time]] -> -0.0020833333 | L33: Completed | M33: Ave. Balboa | N33: P09 | O33: No comments
A34: MX67-HW | B34: Q2FY-8GLS-D4VY | C34: AP | D34: jueves, 12 de febrero de 2026 | E34: 0.33333333 | F34: 0.35555556 | G34: 0.36458333 | H34: 0.40208333 | I34: =H34-G34 -> 0.0375 | J34: =Tabla4[[#This Row],[Planned Time]]-Tabla4[[#This Row],[Arrival time]] -> -0.022222222 | L34: Completed | M34: Town Center | N34: P99 | O34: No comments
A35: MR44-HW | B35: Q3AL-WHKB-7N83 | C35: AP | D35: viernes, 13 de febrero de 2026 | E35: 0.20833333 | F35: 0.21736111 | G35: 0.225 | H35: 0.26041667 | I35: =H35-G35 -> 0.035416667 | J35: =Tabla4[[#This Row],[Planned Time]]-Tabla4[[#This Row],[Arrival time]] -> -0.0090277778 | L35: Completed | M35: Antiguas Vías del Ferrocarril | N35: P12 | O35: No comments
A36: NA | B36: NA | C36: NA | D36: lunes, 16 de febrero de 2026 | E36: NA | L36: NA | M36: NA | N36: NA | O36: No comments
A37: NA | B37: NA | C37: NA | D37: martes, 17 de febrero de 2026 | E37: NA | L37: NA | M37: NA | N37: NA | O37: No comments
A38: NA | B38: NA | C38: NA | D38: miercoles, 18 de febrero de 2026 | E38: NA | L38: NA | M38: NA | N38: NA | O38: No comments
A39: MR44-HW | B39: Q3AL-TNG5-4WUY | C39: AP | D39: jueves, 19 de febrero de 2026 | E39: 0.33333333 | F39: 0.31875 | G39: 0.33611111 | H39: 0.47777778 | I39: =H39-G39 -> 0.14166667 | J39: =Tabla4[[#This Row],[Planned Time]]-Tabla4[[#This Row],[Arrival time]] -> 0.014583333 | L39: Completed | M39: Plaza Comercial Villa Lobos | N39: P28 | O39: No comments
A40: MR44-HW | B40: Q3AL-JDXA-7ZKY | C40: AP | D40: viernes, 20 de febrero de 2026 | E40: 0.20833333 | F40: 0.20416667 | G40: 0.21041667 | H40: 0.27013889 | I40: =H40-G40 -> 0.059722222 | J40: =Tabla4[[#This Row],[Planned Time]]-Tabla4[[#This Row],[Arrival time]] -> 0.0041666667 | L40: Completed | M40: Vía España (Hospital San Fernando) | N40: P08 | O40: No comments
...

Sheet Schedule supervision
A1: Initial Date | B1: Initial Time | C1: Arrival time | D1: Start time
A2: =IF(AND(Control!L5="completed", ISERROR(SEARCH("after the previous", Control!E5))), Control!D5, "") -> 44490 | B2: =IF(A2="", "", Control!E5) -> 0.33333333 | C2: =IF(A2="", "", Control!F5) -> 0.35138889 | D2: =IF(A2="", "", Control!G5) -> 0.35208333
A3: =IF(AND(Control!L6="completed", ISERROR(SEARCH("after the previous", Control!E6))), Control!D6, "") -> 44495 | B3: =IF(A3="", "", Control!E6) -> 0.041666667 | C3: =IF(A3="", "", Control!F6) -> 0.029861111 | D3: =IF(A3="", "", Control!G6) -> 0.03125
A4: =IF(AND(Control!L7="completed", ISERROR(SEARCH("after the previous", Control!E7))), Control!D7, "") -> 44496 | B4: =IF(A4="", "", Control!E7) -> 0.20833333 | C4: =IF(A4="", "", Control!F7) -> 0.20486111 | D4: =IF(A4="", "", Control!G7) -> 0.20694444
A5: =IF(AND(Control!L9="completed", ISERROR(SEARCH("after the previous", Control!E9))), Control!D9, "") -> lunes, 12 de enero de 2026 | B5: =IF(A5="", "", Control!E9) -> 0.29166667 | C5: =IF(A5="", "", Control!F9) -> 0.28472222 | D5: =IF(A5="", "", Control!G9) -> 0.29166667
A6: =IF(AND(Control!L10="completed", ISERROR(SEARCH("after the previous", Control!E10))), Control!D10, "") -> miercoles, 14 de enero de 2026 | B6: =IF(A6="", "", Control!E10) -> 0.16666667 | C6: =IF(A6="", "", Control!F10) -> 0.18402778 | D6: =IF(A6="", "", Control!G10) -> 0.18541667
A7: =IF(AND(Control!L11="completed", ISERROR(SEARCH("after the previous", Control!E11))), Control!D11, "") -> jueves, 15 de enero de 2026 | B7: =IF(A7="", "", Control!E11) -> 0.16666667 | C7: =IF(A7="", "", Control!F11) -> 0.17569444 | D7: =IF(A7="", "", Control!G11) -> 0.17569444
A8: =IF(AND(Control!L13="completed", ISERROR(SEARCH("after the previous", Control!E13))), Control!D13, "") -> viernes, 16 de enero de 2026 | B8: =IF(A8="", "", Control!E13) -> 0.16666667 | C8: =IF(A8="", "", Control!F13) -> 0.16875 | D8: =IF(A8="", "", Control!G13) -> 0.17291667
A9: =IF(AND(Control!L14="completed", ISERROR(SEARCH("after the previous", Control!E14))), Control!D14, "") -> lunes, 19 de enero de 2026 | B9: =IF(A9="", "", Control!E14) -> 0.20833333 | C9: =IF(A9="", "", Control!F14) -> 0.20902778 | D9: =IF(A9="", "", Control!G14) -> 0.21666667
A10: =IF(AND(Control!L16="completed", ISERROR(SEARCH("after the previous", Control!E16))), Control!D16, "") -> miercoles, 21 de enero de 2016 | B10: =IF(A10="", "", Control!E16) -> 0.22916667 | C10: =IF(A10="", "", Control!F16) -> 0.22152778 | D10: =IF(A10="", "", Control!G16) -> 0.22361111
A11: =IF(AND(Control!L17="completed", ISERROR(SEARCH("after the previous", Control!E17))), Control!D17, "") -> jueves, 22 de enero de 2026 | B11: =IF(A11="", "", Control!E17) -> 0.25 | C11: =IF(A11="", "", Control!F17) -> 0.24930556 | D11: =IF(A11="", "", Control!G17) -> 0.25416667
A12: =IF(AND(Control!L18="completed", ISERROR(SEARCH("after the previous", Control!E18))), Control!D18, "") -> viernes, 23 de enero de 2026 | B12: =IF(A12="", "", Control!E18) -> 0.33333333 | C12: =IF(A12="", "", Control!F18) -> 0.29444444 | D12: =IF(A12="", "", Control!G18) -> 0.32291667
A13: =IF(AND(Control!L20="completed", ISERROR(SEARCH("after the previous", Control!E20))), Control!D20, "") -> lunes, 26 de enero de 2026 | B13: =IF(A13="", "", Control!E20) -> 0.20833333 | C13: =IF(A13="", "", Control!F20) -> 0.2125 | D13: =IF(A13="", "", Control!G20) -> 0.21944444
A14: =IF(AND(Control!L23="completed", ISERROR(SEARCH("after the previous", Control!E23))), Control!D23, "") -> martes, 27 de enero de 2026 | B14: =IF(A14="", "", Control!E23) -> 0.20833333 | C14: =IF(A14="", "", Control!F23) -> 0.21180556 | D14: =IF(A14="", "", Control!G23) -> 0.21319444
A15: =IF(AND(Control!L25="completed", ISERROR(SEARCH("after the previous", Control!E25))), Control!D25, "") -> lunes, 02 de febrero de 2026 | B15: =IF(A15="", "", Control!E25) -> 0.29166667 | C15: =IF(A15="", "", Control!F25) -> 0.29513889 | D15: =IF(A15="", "", Control!G25) -> 0.30416667
A16: =IF(AND(Control!L27="completed", ISERROR(SEARCH("after the previous", Control!E27))), Control!D27, "") -> martes, 03 de febrero de 2026 | B16: =IF(A16="", "", Control!E27) -> 0.20833333 | C16: =IF(A16="", "", Control!F27) -> 0.22361111 | D16: =IF(A16="", "", Control!G27) -> 0.22638889
A17: =IF(AND(Control!L28="completed", ISERROR(SEARCH("after the previous", Control!E28))), Control!D28, "") -> miercoles, 04 de febrero de 2026 | B17: =IF(A17="", "", Control!E28) -> 0.20833333 | C17: =IF(A17="", "", Control!F28) -> 0.20763889 | D17: =IF(A17="", "", Control!G28) -> 0.22013889
A18: =IF(AND(Control!L29="completed", ISERROR(SEARCH("after the previous", Control!E29))), Control!D29, "") -> jueves, 05 de febrero de 2026 | B18: =IF(A18="", "", Control!E29) -> 0.20833333 | C18: =IF(A18="", "", Control!F29) -> 0.21597222 | D18: =IF(A18="", "", Control!G29) -> 0.24444444
A19: =IF(AND(Control!L30="completed", ISERROR(SEARCH("after the previous", Control!E30))), Control!D30, "") -> viernes, 06 de febrero de 2026 | B19: =IF(A19="", "", Control!E30) -> 0.20833333 | C19: =IF(A19="", "", Control!F30) -> 0.23402778 | D19: =IF(A19="", "", Control!G30) -> 0.23958333
A20: =IF(AND(Control!L31="completed", ISERROR(SEARCH("after the previous", Control!E31))), Control!D31, "") -> lunes, 09 de febrero de 2026 | B20: =IF(A20="", "", Control!E31) -> 0.20833333 | C20: =IF(A20="", "", Control!F31) -> 0.21111111 | D20: =IF(A20="", "", Control!G31) -> 0.24930556
A21: =IF(AND(Control!L32="completed", ISERROR(SEARCH("after the previous", Control!E32))), Control!D32, "") -> martes, 10 de febrero de 2026 | B21: =IF(A21="", "", Control!E32) -> 0.20833333 | C21: =IF(A21="", "", Control!F32) -> 0.2125 | D21: =IF(A21="", "", Control!G32) -> 0.24861111
A22: =IF(AND(Control!L33="completed", ISERROR(SEARCH("after the previous", Control!E33))), Control!D33, "") -> miercoles, 11 de febrero de 2026 | B22: =IF(A22="", "", Control!E33) -> 0.22916667 | C22: =IF(A22="", "", Control!F33) -> 0.23125 | D22: =IF(A22="", "", Control!G33) -> 0.23263889
A23: =IF(AND(Control!L34="completed", ISERROR(SEARCH("after the previous", Control!E34))), Control!D34, "") -> jueves, 12 de febrero de 2026 | B23: =IF(A23="", "", Control!E34) -> 0.33333333 | C23: =IF(A23="", "", Control!F34) -> 0.35555556 | D23: =IF(A23="", "", Control!G34) -> 0.36458333
A24: =IF(AND(Control!L35="completed", ISERROR(SEARCH("after the previous", Control!E35))), Control!D35, "") -> viernes, 13 de febrero de 2026 | B24: =IF(A24="", "", Control!E35) -> 0.20833333 | C24: =IF(A24="", "", Control!F35) -> 0.21736111 | D24: =IF(A24="", "", Control!G35) -> 0.225
A25: =IF(AND(Control!L39="completed", ISERROR(SEARCH("after the previous", Control!E39))), Control!D39, "") -> jueves, 19 de febrero de 2026 | B25: =IF(A25="", "", Control!E39) -> 0.33333333 | C25: =IF(A25="", "", Control!F39) -> 0.31875 | D25: =IF(A25="", "", Control!G39) -> 0.33611111
A26: =IF(AND(Control!L40="completed", ISERROR(SEARCH("after the previous", Control!E40))), Control!D40, "") -> viernes, 20 de febrero de 2026 | B26: =IF(A26="", "", Control!E40) -> 0.20833333 | C26: =IF(A26="", "", Control!F40) -> 0.20416667 | D26: =IF(A26="", "", Control!G40) -> 0.21041667
A27: =IF(AND(Control!L41="completed", ISERROR(SEARCH("after the previous", Control!E41))), Control!D41, "") -> lunes, 23 de febrero de 2026 | B27: =IF(A27="", "", Control!E41) -> 0.16666667 | C27: =IF(A27="", "", Control!F41) -> 0.16527778 | D27: =IF(A27="", "", Control!G41) -> 0.17013889
A28: =IF(AND(Control!L42="completed", ISERROR(SEARCH("after the previous", Control!E42))), Control!D42, "") -> martes, 24 de febrero de 2026 | B28: =IF(A28="", "", Control!E42) -> 0.20833333 | C28: =IF(A28="", "", Control!F42) -> 0.20138889 | D28: =IF(A28="", "", Control!G42) -> 0.21180556
A29: =IF(AND(Control!L43="completed", ISERROR(SEARCH("after the previous", Control!E43))), Control!D43, "") -> miercoles, 25 de febrero de 2026 | B29: =IF(A29="", "", Control!E43) -> 0.20833333 | C29: =IF(A29="", "", Control!F43) -> 0.20277778 | D29: =IF(A29="", "", Control!G43) -> 0.21458333
A30: =IF(AND(Control!L45="completed", ISERROR(SEARCH("after the previous", Control!E45))), Control!D45, "") -> jueves, 26 de febrero de 2026 | B30: =IF(A30="", "", Control!E45) -> 0.20833333 | C30: =IF(A30="", "", Control!F45) -> 0.20763889 | D30: =IF(A30="", "", Control!G45) -> 0.22083333
A31: =IF(AND(Control!L46="completed", ISERROR(SEARCH("after the previous", Control!E46))), Control!D46, "") -> viernes, 27 de febrero de 2026 | B31: =IF(A31="", "", Control!E46) -> 0.20833333 | C31: =IF(A31="", "", Control!F46) -> 0.21666667 | D31: =IF(A31="", "", Control!G46) -> 0.21944444
A32: =IF(AND(Control!L48="completed", ISERROR(SEARCH("after the previous", Control!E48))), Control!D48, "") -> 44621 | B32: =IF(A32="", "", Control!E48) -> 0.20833333 | C32: =IF(A32="", "", Control!F48) -> 0.21111111 | D32: =IF(A32="", "", Control!G48) -> 0.21458333
A33: =IF(AND(Control!L50="completed", ISERROR(SEARCH("after the previous", Control!E50))), Control!D50, "") -> 44623 | B33: =IF(A33="", "", Control!E50) -> 0.20833333 | C33: =IF(A33="", "", Control!F50) -> 0.20833333 | D33: =IF(A33="", "", Control!G50) -> 0.23958333
A34: =IF(AND(Control!L53="completed", ISERROR(SEARCH("after the previous", Control!E53))), Control!D53, "") -> 44625 | B34: =IF(A34="", "", Control!E53) -> 0.20833333 | C34: =IF(A34="", "", Control!F53) -> 0.20833333 | D34: =IF(A34="", "", Control!G53) -> 0.24166667
A35: =IF(AND(Control!L54="completed", ISERROR(SEARCH("after the previous", Control!E54))), Control!D54, "") -> 44628 | B35: =IF(A35="", "", Control!E54) -> 0.22916667 | C35: =IF(A35="", "", Control!F54) -> 0.23194444 | D35: =IF(A35="", "", Control!G54) -> 0.23472222
A36: =IF(AND(Control!L56="completed", ISERROR(SEARCH("after the previous", Control!E56))), Control!D56, "") -> 44630 | B36: =IF(A36="", "", Control!E56) -> 0.22916667 | C36: =IF(A36="", "", Control!F56) -> 0.23541667 | D36: =IF(A36="", "", Control!G56) -> 0.25625
A37: =IF(AND(Control!L57="completed", ISERROR(SEARCH("after the previous", Control!E57))), Control!D57, "") -> 44632 | B37: =IF(A37="", "", Control!E57) -> 0.39583333 | C37: =IF(A37="", "", Control!F57) -> 0.37986111 | D37: =IF(A37="", "", Control!G57) -> 0.38680556
A38: =IF(AND(Control!L58="completed", ISERROR(SEARCH("after the previous", Control!E58))), Control!D58, "") -> 44635 | B38: =IF(A38="", "", Control!E58) -> 0.20833333 | C38: =IF(A38="", "", Control!F58) -> 0.20972222 | D38: =IF(A38="", "", Control!G58) -> 0.22847222
A39: =IF(AND(Control!L59="completed", ISERROR(SEARCH("after the previous", Control!E59))), Control!D59, "") -> 44637 | B39: =IF(A39="", "", Control!E59) -> 0.20833333 | C39: =IF(A39="", "", Control!F59) -> 0.20416667 | D39: =IF(A39="", "", Control!G59) -> 0.23333333
A40: =IF(AND(Control!L60="completed", ISERROR(SEARCH("after the previous", Control!E60))), Control!D60, "") -> 44639 | B40: =IF(A40="", "", Control!E60) -> 0.20833333 | C40: =IF(A40="", "", Control!F60) -> 0.20138889 | D40: =IF(A40="", "", Control!G60) -> 0.21041667
...
